Workbook

Sheet BACKLOG
A1: REQUISITOS | B1: # | C1: # | D1: DESCRIÇÃO | E1: CLASSIFICAÇÃO | F1: # TAMANHO | G1: FIBONACCI | H1: PRIORIDADE | I1: PRAZO | J1: DATA DE FINALIZAÇÃO | L1: REVISADO | O1: PLANEJADO | P1: ENTREGUE | Q1: PENDENTE
A2: Escolha do TEMA | B2: 1 | C2: 1 | D2: Definir o tema que me represente ou algo do meu gosto | E2: ESSENCIAL | F2: M | G2: =IF(F2="","",_xlfn.XLOOKUP(F2,Listas!$B$2:$B$7,Listas!$C$2:$C$7)) -> 8 | H2: 1 | I2: 45964 | J2: =IF(K2="","",TRUE) -> TRUE | K2: 45962 | L2: FALSE | N2: TOTAL | O2: =SUM(O3:O6) -> 403 | P2: =SUM(P3:P6) -> 249 | Q2: =SUM(Q3:Q6) -> 133
A3: Documentação do projeto | B3: 2 | C3: 1 | D3: Contexto do por que me representa | E3: ESSENCIAL | F3: G | G3: =IF(F3="","",_xlfn.XLOOKUP(F3,Listas!$B$2:$B$7,Listas!$C$2:$C$7)) -> 13 | H3: 2 | I3: 45971 | J3: =IF(K3="","",TRUE) -> TRUE | K3: 45968 | L3: FALSE | N3: 45964 | O3: =SUMPRODUCT(SUMIF($I$2:$I$44,N3,$G$2:$G$44)) -> 50 | P3: =SUMPRODUCT(SUMIFS($G$2:$G$44,$K$2:$K$44,"<="&N3,$J$2:$J$44,TRUE)) -> 71 | Q3: =O3-(SUMPRODUCT(SUMIFS($G$2:$G$44,$I$2:$I$44,N3,$J$2:$J$44,TRUE))) -> 0
B4: 2 | C4: 2 | D4: Objetivo e justificativa do site/projeto | E4: ESSENCIAL | F4: M | G4: =IF(F4="","",_xlfn.XLOOKUP(F4,Listas!$B$2:$B$7,Listas!$C$2:$C$7)) -> 8 | H4: 2 | I4: 45971 | J4: =IF(K4="","",TRUE) -> TRUE | K4: 45964 | L4: FALSE | N4: 45971 | O4: =SUMPRODUCT(SUMIF($I$2:$I$44,N4,$G$2:$G$44)) -> 113 | P4: =SUMPRODUCT(SUMIFS($G$2:$G$44,$K$2:$K$44,">"&N3,$K$2:$K$44,"<="&N4,$J$2:$J$44,TRUE)) -> 108 | Q4: =O4-(SUMPRODUCT(SUMIFS($G$2:$G$44,$I$2:$I$44,N4,$J$2:$J$44,TRUE))) -> 21
B5: 2 | C5: 3 | D5: Escopo | E5: ESSENCIAL | F5: M | G5: =IF(F5="","",_xlfn.XLOOKUP(F5,Listas!$B$2:$B$7,Listas!$C$2:$C$7)) -> 8 | H5: 1 | I5: 45971 | J5: =IF(K5="","",TRUE) -> TRUE | K5: 45964 | L5: FALSE | N5: 45978 | O5: =SUMPRODUCT(SUMIF($I$2:$I$44,N5,$G$2:$G$44)) -> 133 | P5: =SUMPRODUCT(SUMIFS($G$2:$G$44,$K$2:$K$44,">"&N4,$K$2:$K$44,"<="&N5,$J$2:$J$44,TRUE)) -> 70 | Q5: =O5-(SUMPRODUCT(SUMIFS($G$2:$G$44,$I$2:$I$44,N5,$J$2:$J$44,TRUE))) -> 44
B6: 2 | C6: 4 | D6: Determinar a ODS em que o projeto se encaixa | E6: IMPORTANTE | F6: PP | G6: =IF(F6="","",_xlfn.XLOOKUP(F6,Listas!$B$2:$B$7,Listas!$C$2:$C$7)) -> 3 | H6: 2 | I6: 45971 | J6: =IF(K6="","",TRUE) -> TRUE | K6: 45968 | L6: FALSE | N6: 45985 | O6: =SUMPRODUCT(SUMIF($I$2:$I$44,N6,$G$2:$G$44)) -> 107 | P6: =SUMPRODUCT(SUMIFS($G$2:$G$44,$K$2:$K$44,">"&N5,$K$2:$K$44,"<="&N6,$J$2:$J$44,TRUE)) -> 0 | Q6: =O6-(SUMPRODUCT(SUMIFS($G$2:$G$44,$I$2:$I$44,N6,$J$2:$J$44,TRUE))) -> 68
B7: 2 | C7: 5 | D7: Como funciona | E7: DESEJÁVEL | F7: P | G7: =IF(F7="","",_xlfn.XLOOKUP(F7,Listas!$B$2:$B$7,Listas!$C$2:$C$7)) -> 5 | H7: 3 | I7: 45978 | J7: =IF(K7="","",TRUE) | L7: FALSE | N7: MÉDIA | O7: =AVERAGE(O3:O6) -> 100.75 | P7: =AVERAGE(P3:P6) -> 62.25 | Q7: =AVERAGE(Q3:Q6) -> 33.25
A8: Criação do BACKLOG | B8: 3 | C8: 1 | D8: Definir os requisitos do projeto | E8: ESSENCIAL | F8: P | G8: =IF(F8="","",_xlfn.XLOOKUP(F8,Listas!$B$2:$B$7,Listas!$C$2:$C$7)) -> 5 | H8: 1 | I8: 45964 | J8: =IF(K8="","",TRUE) -> TRUE | K8: 45962 | L8: TRUE
B9: 3 | C9: 2 | D9: Classificar os requisitos | E9: IMPORTANTE | F9: P | G9: =IF(F9="","",_xlfn.XLOOKUP(F9,Listas!$B$2:$B$7,Listas!$C$2:$C$7)) -> 5 | H9: 1 | I9: 45964 | J9: =IF(K9="","",TRUE) -> TRUE | K9: 45962 | L9: TRUE
B10: 3 | C10: 3 | D10: Estimar os requisitos | E10: IMPORTANTE | F10: M | G10: =IF(F10="","",_xlfn.XLOOKUP(F10,Listas!$B$2:$B$7,Listas!$C$2:$C$7)) -> 8 | H10: 1 | I10: 45964 | J10: =IF(K10="","",TRUE) -> TRUE | K10: 45962 | L10: TRUE
B11: 3 | C11: 4 | D11: Priorizar os requisitos | E11: IMPORTANTE | F11: M | G11: =IF(F11="","",_xlfn.XLOOKUP(F11,Listas!$B$2:$B$7,Listas!$C$2:$C$7)) -> 8 | H11: 1 | I11: 45964 | J11: =IF(K11="","",TRUE) -> TRUE | K11: 45962 | L11: TRUE
B12: 3 | C12: 5 | D12: Definir os SPRINT BACKLOGs | E12: IMPORTANTE | F12: P | G12: =IF(F12="","",_xlfn.XLOOKUP(F12,Listas!$B$2:$B$7,Listas!$C$2:$C$7)) -> 5 | H12: 1 | I12: 45964 | J12: =IF(K12="","",TRUE) -> TRUE | K12: 45962 | L12: TRUE
A13: Planejamento no Trello | B13: 4 | C13: 1 | D13: Povoar os requisitos do backlog no Trello | E13: IMPORTANTE | F13: M | G13: =IF(F13="","",_xlfn.XLOOKUP(F13,Listas!$B$2:$B$7,Listas!$C$2:$C$7)) -> 8 | H13: 1 | I13: 45964 | J13: =IF(K13="","",TRUE) -> TRUE | K13: 45962 | L13: TRUE
A14: Utilização do Git | B14: 5 | C14: 1 | D14: Criar um repositório para o projeto individual | E14: ESSENCIAL | F14: PP | G14: =IF(F14="","",_xlfn.XLOOKUP(F14,Listas!$B$2:$B$7,Listas!$C$2:$C$7)) -> 3 | H14: 1 | I14: 45964 | J14: =IF(K14="","",TRUE) -> TRUE | K14: 45962 | L14: TRUE
A15: Definição do Dashboard | B15: 6 | C15: 1 | D15: Escolher quais serão os Gráficos | E15: IMPORTANTE | F15: M | G15: =IF(F15="","",_xlfn.XLOOKUP(F15,Listas!$B$2:$B$7,Listas!$C$2:$C$7)) -> 8 | H15: 2 | I15: 45978 | J15: =IF(K15="","",TRUE) -> TRUE | K15: 45970 | L15: FALSE
B16: 6 | C16: 2 | D16: Definir os indicadores (KPI) | E16: IMPORTANTE | F16: M | G16: =IF(F16="","",_xlfn.XLOOKUP(F16,Listas!$B$2:$B$7,Listas!$C$2:$C$7)) -> 8 | H16: 2 | I16: 45978 | J16: =IF(K16="","",TRUE) -> TRUE | K16: 45970 | L16: FALSE
B17: 6 | C17: 3 | D17: Fazer o protótipo do dashboard | E17: IMPORTANTE | F17: G | G17: =IF(F17="","",_xlfn.XLOOKUP(F17,Listas!$B$2:$B$7,Listas!$C$2:$C$7)) -> 13 | H17: 2 | I17: 45971 | J17: =IF(K17="","",TRUE) -> TRUE | K17: 45970 | L17: FALSE
A18: Criação do SITE | B18: 7 | C18: 1 | D18: Fazer o protótipo do site | E18: DESEJÁVEL | F18: GG | G18: =IF(F18="","",_xlfn.XLOOKUP(F18,Listas!$B$2:$B$7,Listas!$C$2:$C$7)) -> 21 | H18: 2 | I18: 45971 | J18: =IF(K18="","",TRUE) | L18: FALSE
B19: 7 | C19: 2 | D19: Header: HTML e CSS | E19: IMPORTANTE | F19: G | G19: =IF(F19="","",_xlfn.XLOOKUP(F19,Listas!$B$2:$B$7,Listas!$C$2:$C$7)) -> 13 | H19: 3 | I19: 45985 | J19: =IF(K19="","",TRUE) -> TRUE | K19: 45971 | L19: FALSE
B20: 7 | C20: 3 | D20: Header: JS (Navegação) | E20: IMPORTANTE | F20: G | G20: =IF(F20="","",_xlfn.XLOOKUP(F20,Listas!$B$2:$B$7,Listas!$C$2:$C$7)) -> 13 | H20: 3 | I20: 45985 | J20: =IF(K20="","",TRUE) -> TRUE | K20: 45974 | L20: FALSE
B21: 7 | C21: 4 | D21: Footer: HTML e CSS | E21: IMPORTANTE | F21: G | G21: =IF(F21="","",_xlfn.XLOOKUP(F21,Listas!$B$2:$B$7,Listas!$C$2:$C$7)) -> 13 | H21: 3 | I21: 45985 | J21: =IF(K21="","",TRUE) -> TRUE | K21: 45971 | L21: FALSE
B22: 7 | C22: 5 | D22: Footer: JS (redirecionar para o Git, Trello) | E22: DESEJÁVEL | F22: G | G22: =IF(F22="","",_xlfn.XLOOKUP(F22,Listas!$B$2:$B$7,Listas!$C$2:$C$7)) -> 13 | H22: 3 | I22: 45985 | J22: =IF(K22="","",TRUE) | L22: FALSE
B23: 7 | C23: 6 | D23: Index: apresentação do site | E23: DESEJÁVEL | F23: G | G23: =IF(F23="","",_xlfn.XLOOKUP(F23,Listas!$B$2:$B$7,Listas!$C$2:$C$7)) -> 13 | H23: 2 | I23: 45978 | J23: =IF(K23="","",TRUE) | L23: FALSE
B24: 7 | C24: 7 | D24: Index: sobre mim e agradecimentos | E24: IMPORTANTE | F24: G | G24: =IF(F24="","",_xlfn.XLOOKUP(F24,Listas!$B$2:$B$7,Listas!$C$2:$C$7)) -> 13 | H24: 2 | I24: 45978 | J24: =IF(K24="","",TRUE) | L24: FALSE
B25: 7 | C25: 8 | D25: Index: como funciona | E25: DESEJÁVEL | F25: M | G25: =IF(F25="","",_xlfn.XLOOKUP(F25,Listas!$B$2:$B$7,Listas!$C$2:$C$7)) -> 8 | H25: 3 | I25: 45985 | J25: =IF(K25="","",TRUE) | L25: FALSE
B26: 7 | C26: 9 | D26: Index: CSS | E26: IMPORTANTE | F26: G | G26: =IF(F26="","",_xlfn.XLOOKUP(F26,Listas!$B$2:$B$7,Listas!$C$2:$C$7)) -> 13 | H26: 3 | I26: 45985 | J26: =IF(K26="","",TRUE) | L26: FALSE
B27: 7 | C27: 10 | D27: Cadastro: HTML | E27: ESSENCIAL | F27: P | G27: =IF(F27="","",_xlfn.XLOOKUP(F27,Listas!$B$2:$B$7,Listas!$C$2:$C$7)) -> 5 | H27: 1 | I27: 45971 | J27: =IF(K27="","",TRUE) -> TRUE | K27: 45977 | L27: FALSE
B28: 7 | C28: 11 | D28: Cadastro: Validações com JS | E28: ESSENCIAL | F28: M | G28: =IF(F28="","",_xlfn.XLOOKUP(F28,Listas!$B$2:$B$7,Listas!$C$2:$C$7)) -> 8 | H28: 2 | I28: 45971 | J28: =IF(K28="","",TRUE) -> TRUE | K28: 45971 | L28: FALSE
B29: 7 | C29: 12 | D29: Cadastro: CSS | E29: IMPORTANTE | F29: G | G29: =IF(F29="","",_xlfn.XLOOKUP(F29,Listas!$B$2:$B$7,Listas!$C$2:$C$7)) -> 13 | H29: 3 | I29: 45978 | J29: =IF(K29="","",TRUE) -> TRUE | K29: 45974 | L29: FALSE
B30: 7 | C30: 13 | D30: Login: HTML | E30: ESSENCIAL | F30: P | G30: =IF(F30="","",_xlfn.XLOOKUP(F30,Listas!$B$2:$B$7,Listas!$C$2:$C$7)) -> 5 | H30: 1 | I30: 45971 | J30: =IF(K30="","",TRUE) -> TRUE | K30: 45971 | L30: FALSE
B31: 7 | C31: 14 | D31: Login: Validações com JS | E31: ESSENCIAL | F31: M | G31: =IF(F31="","",_xlfn.XLOOKUP(F31,Listas!$B$2:$B$7,Listas!$C$2:$C$7)) -> 8 | H31: 2 | I31: 45971 | J31: =IF(K31="","",TRUE) -> TRUE | K31: 45971 | L31: FALSE
B32: 7 | C32: 15 | D32: Login: CSS | E32: IMPORTANTE | F32: G | G32: =IF(F32="","",_xlfn.XLOOKUP(F32,Listas!$B$2:$B$7,Listas!$C$2:$C$7)) -> 13 | H32: 3 | I32: 45978 | J32: =IF(K32="","",TRUE) -> TRUE | K32: 45974 | L32: FALSE
B33: 7 | C33: 16 | D33: Questionário: HTML | E33: ESSENCIAL | F33: P | G33: =IF(F33="","",_xlfn.XLOOKUP(F33,Listas!$B$2:$B$7,Listas!$C$2:$C$7)) -> 5 | H33: 1 | I33: 45978 | J33: =IF(K33="","",TRUE) | L33: FALSE
B34: 7 | C34: 17 | D34: Questionário: Validações com JS | E34: IMPORTANTE | F34: M | G34: =IF(F34="","",_xlfn.XLOOKUP(F34,Listas!$B$2:$B$7,Listas!$C$2:$C$7)) -> 8 | H34: 2 | I34: 45978 | J34: =IF(K34="","",TRUE) | L34: FALSE
B35: 7 | C35: 18 | D35: Questionário: CSS | E35: IMPORTANTE | F35: G | G35: =IF(F35="","",_xlfn.XLOOKUP(F35,Listas!$B$2:$B$7,Listas!$C$2:$C$7)) -> 13 | H35: 3 | I35: 45985 | J35: =IF(K35="","",TRUE) | L35: FALSE
B36: 7 | C36: 19 | D36: DASHBOARD: HTML | E36: ESSENCIAL | F36: P | G36: =IF(F36="","",_xlfn.XLOOKUP(F36,Listas!$B$2:$B$7,Listas!$C$2:$C$7)) -> 5 | H36: 1 | I36: 45978 | J36: =IF(K36="","",TRUE) -> TRUE | K36: 45977 | L36: FALSE
B37: 7 | C37: 20 | D37: DASHBOARD: JS e API | E37: ESSENCIAL | F37: GG | G37: =IF(F37="","",_xlfn.XLOOKUP(F37,Listas!$B$2:$B$7,Listas!$C$2:$C$7)) -> 21 | H37: 2 | I37: 45978 | J37: =IF(K37="","",TRUE) -> TRUE | K37: 45986 | L37: FALSE
B38: 7 | C38: 21 | D38: DASHBOARD: CSS | E38: IMPORTANTE | F38: G | G38: =IF(F38="","",_xlfn.XLOOKUP(F38,Listas!$B$2:$B$7,Listas!$C$2:$C$7)) -> 13 | H38: 3 | I38: 45978 | J38: =IF(K38="","",TRUE) -> TRUE | K38: 45977 | L38: FALSE
A39: Banco de dados no MySQL | B39: 8 | C39: 1 | D39: Criar um usuário próprio para o projeto com conexão no MySQL server dentro da VM na porta 3307 | E39: IMPORTANTE | F39: P | G39: =IF(F39="","",_xlfn.XLOOKUP(F39,Listas!$B$2:$B$7,Listas!$C$2:$C$7)) -> 5 | H39: 1 | I39: 45971 | J39: =IF(K39="","",TRUE) -> TRUE | K39: 45962 | L39: TRUE
B40: 8 | C40: 2 | D40: Criar a modelagem | E40: ESSENCIAL | F40: M | G40: =IF(F40="","",_xlfn.XLOOKUP(F40,Listas!$B$2:$B$7,Listas!$C$2:$C$7)) -> 8 | H40: 2 | I40: 45971 | J40: =IF(K40="","",TRUE) -> TRUE | K40: 45970 | L40: FALSE
...

Sheet Listas
A1: CLASSIFICAÇÃO | B1: # TAMANHO | C1: FIBONACCI | D1: PRIORIDADE | E1: PRAZO
A2: ESSENCIAL | B2: PP | C2: 3 | D2: 1 | E2: 45964
A3: IMPORTANTE | B3: P | C3: 5 | D3: 2 | E3: 45971
A4: DESEJÁVEL | B4: M | C4: =SUM(C2:C3) -> 8 | D4: 3 | E4: 45978
B5: G | C5: =SUM(C3:C4) -> 13 | E5: 45985
B6: GG | C6: =SUM(C4:C5) -> 21
